<?xml version='1.0' encoding='utf-8'?>
<mujoco model="Arm_6Dof">
  <compiler angle="radian" />
  <asset>
    <mesh name="base_link" file="/home/wang/Griparm/Arm_6Dof_claw_urdf/meshes/base_link.STL" />
    <mesh name="Jianbu_Link" file="/home/wang/Griparm/Arm_6Dof_claw_urdf/meshes/Jianbu_Link.STL" />
    <mesh name="Dabi_Link" file="/home/wang/Griparm/Arm_6Dof_claw_urdf/meshes/Dabi_Link.STL" />
    <mesh name="Upper_Link" file="/home/wang/Griparm/Arm_6Dof_claw_urdf/meshes/Upper_Link.STL" />
    <mesh name="Lower_Link" file="/home/wang/Griparm/Arm_6Dof_claw_urdf/meshes/Lower_Link.STL" />
    <mesh name="Wrist_Link" file="/home/wang/Griparm/Arm_6Dof_claw_urdf/meshes/Wrist_Link.STL" />
    <mesh name="Hand_Link" file="/home/wang/Griparm/Arm_6Dof_claw_urdf/meshes/Hand_Link.STL" />
    <mesh name="Claw_Link_left" file="/home/wang/Griparm/Arm_6Dof_claw_urdf/meshes/Claw_Link_left.STL" />
    <mesh name="Claw_Link_right" file="/home/wang/Griparm/Arm_6Dof_claw_urdf/meshes/Claw_Link_right.STL" />
    <material name="normal_pine_mat" rgba="0.88 0.72 0.51 1" specular="0.25" shininess="0.3" /><material name="anomaly_pine_mat" rgba="0.96 0.46 0.24 1" specular="0.25" shininess="0.3" /><mesh name="anomaly_mesh" file="/home/wang/Griparm/Sample/Anomaly.STL" scale="0.001 0.001 0.001" />
    <mesh name="normal_mesh" file="/home/wang/Griparm/Sample/Normal.STL" scale="0.001 0.001 0.001" />
    </asset>
  <worldbody>
    <geom type="mesh" rgba="0.28 0.52 0.78 1" mesh="base_link" />
    <body name="Jianbu_Link" pos="0 0 0.11">
      <inertial pos="9.23183e-07 0.00144533 -0.00141989" quat="-0.0658672 0.704028 -0.0658694 0.704036" mass="4.04937" diaginertia="0.00980754 0.00778529 0.00738331" />
      <joint name="J_jianbu" pos="0 0 0" axis="0 0 1" damping="15" />
      <geom type="mesh" rgba="0.72 0.44 0.22 1" mesh="Jianbu_Link" />
      <body name="Dabi_Link" pos="0 0 0.065" quat="0.707105 0.707108 0 0">
        <inertial pos="0.018356 0.184107 0.00441773" quat="0.72504 0.667747 0.0512032 -0.160655" mass="1.60883" diaginertia="0.0102705 0.0101173 0.00112287" />
        <joint name="J_dabi" pos="0 0 0" axis="0 0 1" range="-1.7453 1.7453" actuatorfrcrange="-40 40" damping="15" />
        <geom type="mesh" rgba="0.62 0.7 0.28 1" mesh="Dabi_Link" />
        <body name="Upper_Link" pos="0.04461 0.3 0" quat="0.707105 0 0 -0.707108">
          <inertial pos="5.87978e-05 0.0877738 0" quat="0.707106 0.707106 -0.000805091 -0.000805091" mass="0.215621" diaginertia="0.00046231 0.000264364 0.000247247" />
          <joint name="J_Upper" pos="0 0 0" axis="0 0 1" range="-1.0472 1.5708" actuatorfrcrange="-25 25" damping="15" />
          <geom type="mesh" rgba="0.34 0.4 0.82 1" mesh="Upper_Link" />
          <body name="Lower_Link" pos="0 0.15539 0" quat="0.499998 -0.5 -0.5 -0.500002">
            <inertial pos="-0.00725575 9.8398e-09 0.0674548" quat="0.698816 0.107963 0.107963 0.698816" mass="0.349998" diaginertia="0.000294328 0.000194031 0.000159248" />
            <joint name="J_Lower" pos="0 0 0" axis="0 0 -1" damping="15" />
            <geom type="mesh" rgba="0.25 0.7 0.54 1" mesh="Lower_Link" />
            <body name="Wrist_Link" pos="0 0 0.1" quat="0.499998 0.5 0.500002 0.5">
              <inertial pos="-0.00915921 0.0414527 -1.52017e-08" quat="0.692992 0.693005 0.140511 0.140575" mass="0.133743" diaginertia="5.46419e-05 5.39198e-05 3.45458e-05" />
              <joint name="J_wrist" pos="0 0 0" axis="0 0 1" range="-1.5708 1.5708" damping="15" />
              <geom type="mesh" rgba="0.86 0.56 0.3 1" mesh="Wrist_Link" />
              <body name="Hand_Link" pos="0 0.074 0" quat="0.499998 -0.5 -0.5 -0.500002">
                <inertial pos="1.76947e-07 -0.00858821 0.046799" quat="0.410985 0.575408 0.410983 0.575405" mass="0.247084" diaginertia="0.000194449 0.000172493 7.59311e-05" />
                <joint name="J_hand" pos="0 0 0" axis="0 0 -1" damping="15" />
                <geom type="mesh" rgba="0.3 0.34 0.4 1" mesh="Hand_Link" />
                <body name="Claw_Link_left" pos="0 0 0.07">
                  <inertial pos="0.043195 -0.0037299 0.0066554" quat="0.499437 0.513058 0.549557 0.430488" mass="0.031566" diaginertia="8.03799e-06 6.42893e-06 3.54388e-06" />
                  <joint name="Claw_left" pos="0 0 0" axis="-1 0 0" type="slide" range="0 0.04" damping="30" />
                  <geom type="mesh" rgba="0.32 0.46 0.8 1" mesh="Claw_Link_left" friction="1.5 0.2 0.02" condim="6" solref="0.02 1" solimp="0.9 0.95 0.003" margin="0.0005" />
                  </body>
                <body name="Claw_Link_right" pos="0 0 0.07" quat="-3.67321e-06 0 0 1">
                  <inertial pos="0.043195 -0.0037299 0.0066554" quat="0.499437 0.513058 0.549557 0.430488" mass="0.031566" diaginertia="8.03799e-06 6.42893e-06 3.54388e-06" />
                  <joint name="claw_right" pos="0 0 0" axis="1 0 0" type="slide" range="-0.04 0" damping="30" />
                  <geom type="mesh" rgba="0.32 0.46 0.8 1" mesh="Claw_Link_right" friction="1.5 0.2 0.02" condim="6" solref="0.02 1" solimp="0.9 0.95 0.003" margin="0.0005" />
                  </body>
                <site name="tcp_site" type="sphere" size="0.004" pos="0.045 0.0 0.070" rgba="1 0.1 0.1 1" />
                <camera name="wrist" mode="fixed" pos="0.000000 -0.043463 0.050819" quat="0.052336 0.998630 0.000000 0.000000" fovy="58" />
                </body>
              </body>
            </body>
          </body>
        </body>
      </body>
    <camera name="global" mode="fixed" pos="-0.174214 0.000000 1.137303" quat="0.680357 0.192649 -0.192649 -0.680357" fovy="45" />
    <geom name="table" type="box" pos="0.10 0.00 0.00" size="0.70 0.45 0.02" rgba="0.25 0.25 0.25 1" friction="1.0 0.005 0.0001" />
    <body name="anomaly_0" pos="-0.40 0.10 0.02">
      <freejoint name="anomaly_0_free" />
      <geom name="anomaly_0_geom" type="mesh" mesh="anomaly_mesh" material="anomaly_pine_mat" mass="0.06" friction="1.0 0.05 0.005" condim="6" solref="0.01 1" solimp="0.9 0.99 0.001" />
      </body>
    <body name="normal_0" pos="-0.500 -0.100 0.02">
      <freejoint name="normal_0_free" />
      <geom name="normal_0_geom" type="mesh" mesh="normal_mesh" material="normal_pine_mat" mass="0.06" friction="1.0 0.05 0.005" condim="6" solref="0.01 1" solimp="0.9 0.99 0.001" />
      </body>
    <body name="normal_1" pos="-0.460 -0.160 0.02">
      <freejoint name="normal_1_free" />
      <geom name="normal_1_geom" type="mesh" mesh="normal_mesh" material="normal_pine_mat" mass="0.06" friction="1.0 0.05 0.005" condim="6" solref="0.01 1" solimp="0.9 0.99 0.001" />
      </body>
    <body name="normal_2" pos="-0.420 -0.220 0.02">
      <freejoint name="normal_2_free" />
      <geom name="normal_2_geom" type="mesh" mesh="normal_mesh" material="normal_pine_mat" mass="0.06" friction="1.0 0.05 0.005" condim="6" solref="0.01 1" solimp="0.9 0.99 0.001" />
      </body>
    <body name="normal_3" pos="-0.380 -0.280 0.02">
      <freejoint name="normal_3_free" />
      <geom name="normal_3_geom" type="mesh" mesh="normal_mesh" material="normal_pine_mat" mass="0.06" friction="1.0 0.05 0.005" condim="6" solref="0.01 1" solimp="0.9 0.99 0.001" />
      </body>
    <body name="normal_4" pos="-0.340 -0.340 0.02">
      <freejoint name="normal_4_free" />
      <geom name="normal_4_geom" type="mesh" mesh="normal_mesh" material="normal_pine_mat" mass="0.06" friction="1.0 0.05 0.005" condim="6" solref="0.01 1" solimp="0.9 0.99 0.001" />
      </body>
    <body name="layout_conveyor" pos="0.440000 0.000000 0.010000" quat="0.707107 0.000000 0.000000 0.707107"><geom name="layout_conveyor_geom" type="box" size="0.600000 0.110000 0.010000" rgba="0.52 0.52 0.52 0.95" contype="0" conaffinity="0" /><site name="layout_conveyor_start" pos="-0.600000 0 0" size="0.01" rgba="0.6 0.6 0.6 1" /><site name="layout_conveyor_end" pos="0.600000 0 0" size="0.01" rgba="0.6 0.6 0.6 1" /></body><body name="layout_place_region" pos="0.120000 -0.400000 0.002000" quat="1.000000 0.000000 0.000000 0.000000"><geom name="layout_place_region_geom" type="cylinder" size="0.150000 0.002000" rgba="1.0 0.35 0.68 0.45" contype="0" conaffinity="0" /><site name="layout_place_center" pos="0 0 0" size="0.01" rgba="1.0 0.35 0.68 1" /></body></worldbody>
  <option timestep="0.002" gravity="0 0 -9.81" cone="elliptic" impratio="10" solver="Newton" iterations="200" noslip_iterations="2" />
  <actuator>
    <position name="J_jianbu_pos" joint="J_jianbu" kp="80" ctrlrange="-3.1416 3.1416" ctrllimited="true" />
    <position name="J_dabi_pos" joint="J_dabi" kp="80" ctrlrange="-3.1416 3.1416" ctrllimited="true" />
    <position name="J_Upper_pos" joint="J_Upper" kp="80" ctrlrange="-3.1416 3.1416" ctrllimited="true" />
    <position name="J_Lower_pos" joint="J_Lower" kp="80" ctrlrange="-3.1416 3.1416" ctrllimited="true" />
    <position name="J_wrist_pos" joint="J_wrist" kp="80" ctrlrange="-3.1416 3.1416" ctrllimited="true" />
    <position name="J_hand_pos" joint="J_hand" kp="80" ctrlrange="-3.1416 3.1416" ctrllimited="true" />
    <position name="Claw_left_pos" joint="Claw_left" kp="600" ctrlrange="0.0 0.04" ctrllimited="true" forcerange="-200 200" forcelimited="true" />
    <position name="Claw_right_pos" joint="claw_right" kp="600" ctrlrange="-0.04 0.0" ctrllimited="true" forcerange="-200 200" forcelimited="true" /></actuator>
  <visual>
    <global offwidth="256" offheight="256" />
    </visual>
  <contact><exclude body1="Claw_Link_left" body2="Hand_Link" /><exclude body1="Claw_Link_right" body2="Hand_Link" /><exclude body1="Claw_Link_left" body2="Claw_Link_right" /></contact></mujoco>